<?xml version="1.0" ?>
<robot name="line" xmlns:xacro="http://www.ros.org/wiki/xacro">

<xacro:include filename="$(find line_description)/urdf/materials.xacro" />
<xacro:include filename="$(find line_description)/urdf/line.trans" />
<xacro:include filename="$(find line_description)/urdf/line.gazebo" />
<link name="base_link">
  <inertial>
    <origin xyz="0.014622929471341134 -4.7231053537326336e-17 0.002295605197538432" rpy="0 0 0"/>
    <mass value="1.5116184955042697"/>
    <inertia ixx="0.001333" iyy="0.00529" izz="0.006107" ixy="-0.0" iyz="-0.0" ixz="-0.000301"/>
  </inertial>
  <visual>
    <origin xyz="0 0 0" rpy="0 0 0"/>
    <geometry>
      <mesh filename="package://line_description/meshes/base_link.stl" scale="0.001 0.001 0.001"/>
    </geometry>
    <material name="silver"/>
  </visual>
  <collision>
    <origin xyz="0 0 0" rpy="0 0 0"/>
    <geometry>
      <mesh filename="package://line_description/meshes/base_link.stl" scale="0.001 0.001 0.001"/>
    </geometry>
  </collision>
</link>

<link name="left_wheel_1">
  <inertial>
    <origin xyz="1.3877787807814457e-17 0.0025000000000000022 1.0408340855860843e-17" rpy="0 0 0"/>
    <mass value="0.11097676048805935"/>
    <inertia ixx="2.5e-05" iyy="5e-05" izz="2.5e-05" ixy="0.0" iyz="0.0" ixz="0.0"/>
  </inertial>
  <visual>
    <origin xyz="0.08 -0.055 0.02" rpy="0 0 0"/>
    <geometry>
      <mesh filename="package://line_description/meshes/left_wheel_1.stl" scale="0.001 0.001 0.001"/>
    </geometry>
    <material name="silver"/>
  </visual>
  <collision>
    <origin xyz="0.08 -0.055 0.02" rpy="0 0 0"/>
    <geometry>
      <mesh filename="package://line_description/meshes/left_wheel_1.stl" scale="0.001 0.001 0.001"/>
    </geometry>
  </collision>
</link>

<link name="right_wheel_1">
  <inertial>
    <origin xyz="1.3877787807814457e-17 -0.0025000000000000022 0.0" rpy="0 0 0"/>
    <mass value="0.1109767604880594"/>
    <inertia ixx="2.5e-05" iyy="5e-05" izz="2.5e-05" ixy="0.0" iyz="0.0" ixz="0.0"/>
  </inertial>
  <visual>
    <origin xyz="0.08 0.055 0.02" rpy="0 0 0"/>
    <geometry>
      <mesh filename="package://line_description/meshes/right_wheel_1.stl" scale="0.001 0.001 0.001"/>
    </geometry>
    <material name="silver"/>
  </visual>
  <collision>
    <origin xyz="0.08 0.055 0.02" rpy="0 0 0"/>
    <geometry>
      <mesh filename="package://line_description/meshes/right_wheel_1.stl" scale="0.001 0.001 0.001"/>
    </geometry>
  </collision>
</link>

<link name="lidar_1">
  <inertial>
    <origin xyz="7.450580569168253e-10 1.7763568394002505e-17 0.015" rpy="0 0 0"/>
    <mass value="0.46240316870024756"/>
    <inertia ixx="0.000107" iyy="0.000107" izz="0.000145" ixy="0.0" iyz="0.0" ixz="0.0"/>
  </inertial>
  <visual>
    <origin xyz="-0.05 -0.0 -0.025" rpy="0 0 0"/>
    <geometry>
      <mesh filename="package://line_description/meshes/lidar_1.stl" scale="0.001 0.001 0.001"/>
    </geometry>
    <material name="silver"/>
  </visual>
  <collision>
    <origin xyz="-0.05 -0.0 -0.025" rpy="0 0 0"/>
    <geometry>
      <mesh filename="package://line_description/meshes/lidar_1.stl" scale="0.001 0.001 0.001"/>
    </geometry>
  </collision>
</link>

<joint name="Rev1" type="continuous">
  <origin xyz="-0.08 0.055 -0.02" rpy="0 0 0"/>
  <parent link="base_link"/>
  <child link="left_wheel_1"/>
  <axis xyz="0.0 1.0 0.0"/>
</joint>

<joint name="Rev2" type="continuous">
  <origin xyz="-0.08 -0.055 -0.02" rpy="0 0 0"/>
  <parent link="base_link"/>
  <child link="right_wheel_1"/>
  <axis xyz="0.0 1.0 0.0"/>
</joint>

<joint name="Rev3" type="continuous">
  <origin xyz="0.05 0.0 0.025" rpy="0 0 0"/>
  <parent link="base_link"/>
  <child link="lidar_1"/>
  <axis xyz="0.0 0.0 1.0"/>
</joint>

</robot>
